<robot name="onshape">

<link name="base">
<visual>
<origin xyz="0.005 0 0.278" rpy="1.570796326794896558 -0 -1.570796326794896558" />
<geometry>
<mesh filename="package:///workspace/robots/models/base.stl"/>
</geometry>
<material name="base_material">
<color rgba="0.15686274509803921351 0.15686274509803921351 0.15686274509803921351 1.0"/>
</material>
</visual>
<collision>
<origin xyz="0.005 0 0.278" rpy="1.570796326794896558 -0 -1.570796326794896558" />
<geometry>
<mesh filename="package:///workspace/robots/models/base.stl"/>
</geometry>
</collision>
<inertial>
<origin xyz="-0.00011265867616427026332 -4.5386811759117257005e-05 0.017135759761536861756" rpy="0 0 0"/>
<mass value="0.42841802966019687515" />
<inertia ixx="0.00064602507988347260791" ixy="-2.2001300436442401969e-05"  ixz="6.5364849276818986554e-07" iyy="0.00068995950799835580915" iyz="2.6354237622342715372e-07" izz="0.0012406260133752415511" />
</inertial>
</link>

<link name="carriage_1">
<visual>
<origin xyz="0 -0.005 -0.24" rpy="-1.570796326794896558 -0 0" />
<geometry>
<mesh filename="package:///workspace/robots/models/carriage_1.stl"/>
</geometry>
<material name="carriage_1_material">
<color rgba="0 0 1 1.0"/>
</material>
</visual>
<collision>
<origin xyz="0 -0.005 -0.24" rpy="-1.570796326794896558 -0 0" />
<geometry>
<mesh filename="package:///workspace/robots/models/carriage_1.stl"/>
</geometry>
</collision>
<inertial>
<origin xyz="-0.023150399814567530071 -6.8452453490545558945e-06 -0.051939322559866489548" rpy="0 0 0"/>
<mass value="0.41482347331597585471" />
<inertia ixx="0.00086760620138834126588" ixy="2.0975973300442710159e-07"  ixz="-5.335461068506447234e-05" iyy="0.00090177245271764712789" iyz="-1.3396468832869947513e-08" izz="0.0011302714548553933344" />
</inertial>
</link>

<link name="shoulder_lift">
<visual>
<origin xyz="0.185 -0.005 0.066" rpy="-1.570796326794896558 -1.570796326794896558 0" />
<geometry>
<mesh filename="package:///workspace/robots/models/abs_pipe_-_3&quot;.stl"/>
</geometry>
<material name="abs_pipe_-_3&quot;_material">
<color rgba="0.15686274509803921351 0.15686274509803921351 0.15686274509803921351 1.0"/>
</material>
</visual>
<collision>
<origin xyz="0.185 -0.005 0.066" rpy="-1.570796326794896558 -1.570796326794896558 0" />
<geometry>
<mesh filename="package:///workspace/robots/models/abs_pipe_-_3&quot;.stl"/>
</geometry>
</collision>
<visual>
<origin xyz="0.18492527692447696674 -0.005002337924161806039 0.066073318972919486969" rpy="-1.570796326794896558 -1.570796326794896336 0" />
<geometry>
<mesh filename="package:///workspace/robots/models/link_carriage.stl"/>
</geometry>
<material name="link_carriage_material">
<color rgba="0 0 1 1.0"/>
</material>
</visual>
<collision>
<origin xyz="0.18492527692447696674 -0.005002337924161806039 0.066073318972919486969" rpy="-1.570796326794896558 -1.570796326794896336 0" />
<geometry>
<mesh filename="package:///workspace/robots/models/link_carriage.stl"/>
</geometry>
</collision>
<visual>
<origin xyz="0.185 -0.0048 0.066" rpy="-1.570796326794896558 -1.570796326794896558 0" />
<geometry>
<mesh filename="package:///workspace/robots/models/carriage_2.stl"/>
</geometry>
<material name="carriage_2_material">
<color rgba="0 0 1 1.0"/>
</material>
</visual>
<collision>
<origin xyz="0.185 -0.0048 0.066" rpy="-1.570796326794896558 -1.570796326794896558 0" />
<geometry>
<mesh filename="package:///workspace/robots/models/carriage_2.stl"/>
</geometry>
</collision>
<inertial>
<origin xyz="0.02315029420940292737 6.8343455309500394934e-06 -0.05193936685330259595" rpy="0 0 0"/>
<mass value="0.41482359472485302865" />
<inertia ixx="0.00086760335304015884141" ixy="2.0620860157982380339e-07"  ixz="5.3355089090974940167e-05" iyy="0.00090177397441154171637" iyz="1.1881109004419204797e-08" izz="0.0011302709841813816331" />
</inertial>
</link>

<link name="elbow">
<visual>
<origin xyz="-0.165 0.005 -0.065" rpy="1.570796326794896558 1.570796326794896558 0" />
<geometry>
<mesh filename="package:///workspace/robots/models/knee_cap.stl"/>
</geometry>
<material name="knee_cap_material">
<color rgba="0.15686274509803921351 0.15686274509803921351 0.15686274509803921351 1.0"/>
</material>
</visual>
<collision>
<origin xyz="-0.165 0.005 -0.065" rpy="1.570796326794896558 1.570796326794896558 0" />
<geometry>
<mesh filename="package:///workspace/robots/models/knee_cap.stl"/>
</geometry>
</collision>
<visual>
<origin xyz="-0.168 0.005 -0.065" rpy="1.570796326794896558 1.5707963267948950037 0" />
<geometry>
<mesh filename="package:///workspace/robots/models/abs_pipe_-_2&quot;.stl"/>
</geometry>
<material name="abs_pipe_-_2&quot;_material">
<color rgba="0.15686274509803921351 0.15686274509803921351 0.15686274509803921351 1.0"/>
</material>
</visual>
<collision>
<origin xyz="-0.168 0.005 -0.065" rpy="1.570796326794896558 1.5707963267948950037 0" />
<geometry>
<mesh filename="package:///workspace/robots/models/abs_pipe_-_2&quot;.stl"/>
</geometry>
</collision>
<visual>
<origin xyz="-0.168 0.005 -0.065" rpy="1.570796326794896558 1.5707963267948950037 0" />
<geometry>
<mesh filename="package:///workspace/robots/models/wrist_carriage_1.stl"/>
</geometry>
<material name="wrist_carriage_1_material">
<color rgba="0 0 1 1.0"/>
</material>
</visual>
<collision>
<origin xyz="-0.168 0.005 -0.065" rpy="1.570796326794896558 1.5707963267948950037 0" />
<geometry>
<mesh filename="package:///workspace/robots/models/wrist_carriage_1.stl"/>
</geometry>
</collision>
<inertial>
<origin xyz="0 0 0" rpy="0 0 0"/>
<mass value="0" />
<inertia ixx="0" ixy="0"  ixz="0" iyy="0" iyz="0" izz="0" />
</inertial>
</link>

<link name="wrist_carriage_2">
<visual>
<origin xyz="-0.488 -0.005 0.041" rpy="-1.570796326794896558 -1.570796326794896558 0" />
<geometry>
<mesh filename="package:///workspace/robots/models/wrist_carriage_2.stl"/>
</geometry>
<material name="wrist_carriage_2_material">
<color rgba="0 0 1 1.0"/>
</material>
</visual>
<collision>
<origin xyz="-0.488 -0.005 0.041" rpy="-1.570796326794896558 -1.570796326794896558 0" />
<geometry>
<mesh filename="package:///workspace/robots/models/wrist_carriage_2.stl"/>
</geometry>
</collision>
<inertial>
<origin xyz="0 0 0" rpy="0 0 0"/>
<mass value="0" />
<inertia ixx="0" ixy="0"  ixz="0" iyy="0" iyz="0" izz="0" />
</inertial>
</link>

<link name="wrist_carriage_3">
<visual>
<origin xyz="0.0895 -0.005 0.53" rpy="-1.570796326794896558 0 0" />
<geometry>
<mesh filename="package:///workspace/robots/models/wrist_carriage_3.stl"/>
</geometry>
<material name="wrist_carriage_3_material">
<color rgba="0 0 1 1.0"/>
</material>
</visual>
<collision>
<origin xyz="0.0895 -0.005 0.53" rpy="-1.570796326794896558 0 0" />
<geometry>
<mesh filename="package:///workspace/robots/models/wrist_carriage_3.stl"/>
</geometry>
</collision>
<inertial>
<origin xyz="0 0 0" rpy="0 0 0"/>
<mass value="0" />
<inertia ixx="0" ixy="0"  ixz="0" iyy="0" iyz="0" izz="0" />
</inertial>
</link>

<joint name="wrist_2" type="revolute">
<origin xyz="0.04 0 -0.0485" rpy="0 -1.570796326794896558 0" />
<parent link="wrist_carriage_2" />
<child link="wrist_carriage_3" />
<axis xyz="0 0 1"/>
<limit effort="1" velocity="20" />
<joint_properties friction="0.0"/>
</joint>

<joint name="wrist_1" type="revolute">
<origin xyz="0.32 0 -0.025" rpy="3.1415926535897922278 0 0" />
<parent link="elbow" />
<child link="wrist_carriage_2" />
<axis xyz="0 0 1"/>
<limit effort="1" velocity="20" />
<joint_properties friction="0.0"/>
</joint>

<joint name="shoulder_bend" type="revolute">
<origin xyz="0.35 0 0" rpy="-3.141592653589793116 0 0" />
<parent link="shoulder_lift" />
<child link="elbow" />
<axis xyz="0 0 1"/>
<limit effort="1" velocity="20" />
<joint_properties friction="0.0"/>
</joint>

<joint name="shoulder_lift" type="revolute">
<origin xyz="-0.065 0 -0.055" rpy="0 1.5707963267948923392 0" />
<parent link="carriage_1" />
<child link="shoulder_lift" />
<axis xyz="0 0 1"/>
<limit effort="1" velocity="20" />
<joint_properties friction="0.0"/>
</joint>

<joint name="shoulder_rotate" type="revolute">
<origin xyz="0 0 0.037" rpy="-3.141592653589793116 0 0" />
<parent link="base" />
<child link="carriage_1" />
<axis xyz="0 0 1"/>
<limit effort="1" velocity="20" />
<joint_properties friction="0.0"/>
</joint>


</robot>
